Thread 1 killed on uncaught exception Uncaught_exception_handler.CallbackExn
Raised at Uncaught_exception_handler.fn in file "uncaught_exception_handler.ml", lines 30-31, characters 2-47
Called from Thread.create.(fun) in file "thread.ml", line 53, characters 8-14
[thread 2] caught Uncaught_exception_handler.CallbackExn
Raised at Uncaught_exception_handler.fn in file "uncaught_exception_handler.ml", lines 30-31, characters 2-79
Called from Thread.create.(fun) in file "thread.ml", line 53, characters 8-14
Thread 2 killed on uncaught exception Uncaught_exception_handler.CallbackExn
Raised at Uncaught_exception_handler.fn in file "uncaught_exception_handler.ml", lines 30-31, characters 2-79
Called from Thread.create.(fun) in file "thread.ml", line 53, characters 8-14
Thread 2 uncaught exception handler raised Uncaught_exception_handler.UncaughtHandlerExn
Raised at Uncaught_exception_handler.handler in file "uncaught_exception_handler.ml", line 26, characters 2-17
Called from Thread.create.(fun) in file "thread.ml", line 62, characters 10-62
[thread 3] caught Uncaught_exception_handler.CallbackExn
Raised at Uncaught_exception_handler.fn in file "uncaught_exception_handler.ml", lines 30-31, characters 2-79
Called from Thread.create.(fun) in file "thread.ml", line 53, characters 8-14
